Workbook

Sheet SDC Calculator
A1: SDC Formulation Calculator — period-based thumb rules (synthesis / early STA)
A2: Yellow + blue text = USER INPUTS (edit these). Green = calculated. Pick % of period T from dropdowns. Optional floor clamps (ps) apply via MAX(T×%, floor). Starting points only — replace with board/IP/signoff numbers.
A4: CLOCK INPUTS
A5: Clock name | B5: CLK | C5: ← edit
A6: Period T | B6: 4 | C6: ← edit (e.g. 2.0 for 500 MHz if unit=ns)
A7: Time unit | B7: ns | C7: ← ns or ps
A8: Frequency (MHz) | B8: =IF(B7="ns",1000/B6,IF(B7="ps",1000000/B6,"—")) -> 250 | C8: formula: if ns → 1000/T ; if ps → 1e6/T
A9: 5% of T (ref) | B9: =0.05*B6 -> 0.2 | C9: quick reference slice of period
A11: CONSTRAINT TABLE — select percentile for each parameter → value = MAX(T × pct, floor)
A12: Parameter | B12: Applies to | C12: Profile / notes | D12: Percentile of T | E12: % (decimal) | F12: Floor (same unit as T) | G12: Calculated value | H12: Unit | I12: SDC command (template) | J12: Notes
A13: Setup uncertainty | B13: clocks (setup) | C13: early synth ~3–7% T | D13: 0.05 | E13: =D13 -> 0.05 | F13: 0.05 | G13: =MAX($B$6*D13,F13) -> 0.2 | H13: =$B$7 -> ns | I13: =CONCATENATE("set_clock_uncertainty -setup ",TEXT(G13,"0.000")," [get_clocks ",$B$5,"]") -> set_clock_uncertainty -setup 0.200 [get_clocks CLK] | J13: ↑ harder setup; later refined by derates/jitter
A14: Hold uncertainty | B14: clocks (hold) | C14: early ~1–3% T | D14: 0.02 | E14: =D14 -> 0.02 | F14: 0.02 | G14: =MAX($B$6*D14,F14) -> 0.08 | H14: =$B$7 -> ns | I14: =CONCATENATE("set_clock_uncertainty -hold ",TEXT(G14,"0.000")," [get_clocks ",$B$5,"]") -> set_clock_uncertainty -hold 0.080 [get_clocks CLK] | J14: ↑ harder hold; often floor 20–50 ps
A15: Input delay max | B15: inputs → capture | C15: early ~20–40% T | D15: 0.3 | E15: =D15 -> 0.3 | F15: 0 | G15: =MAX($B$6*D15,F15) -> 1.2 | H15: =$B$7 -> ns | I15: =CONCATENATE("set_input_delay -max ",TEXT(G15,"0.000")," -clock ",$B$5," [all_inputs]") -> set_input_delay -max 1.200 -clock CLK [all_inputs] | J15: external launch budget; don't double-count pads
A16: Input delay min | B16: inputs (hold) | C16: early ~0–10% T | D16: 0.1 | E16: =D16 -> 0.1 | F16: 0 | G16: =MAX($B$6*D16,F16) -> 0.4 | H16: =$B$7 -> ns | I16: =CONCATENATE("set_input_delay -min ",TEXT(G16,"0.000")," -clock ",$B$5," [all_inputs]") -> set_input_delay -min 0.400 -clock CLK [all_inputs] | J16: often ¼–½ of max; near 0 if aggressive
A17: Output delay max | B17: launch → outputs | C17: early ~20–40% T | D17: 0.3 | E17: =D17 -> 0.3 | F17: 0 | G17: =MAX($B$6*D17,F17) -> 1.2 | H17: =$B$7 -> ns | I17: =CONCATENATE("set_output_delay -max ",TEXT(G17,"0.000")," -clock ",$B$5," [all_outputs]") -> set_output_delay -max 1.200 -clock CLK [all_outputs] | J17: external capture budget
A18: Output delay min | B18: outputs (hold) | C18: early ~0–10% T | D18: 0.1 | E18: =D18 -> 0.1 | F18: 0 | G18: =MAX($B$6*D18,F18) -> 0.4 | H18: =$B$7 -> ns | I18: =CONCATENATE("set_output_delay -min ",TEXT(G18,"0.000")," -clock ",$B$5," [all_outputs]") -> set_output_delay -min 0.400 -clock CLK [all_outputs] | J18: pair with max; hold on R2O/I2O
A19: Input transition max | B19: all_inputs slew | C19: early ~5–15% T or fixed ps | D19: 0.075 | E19: =D19 -> 0.075 | F19: 0 | G19: =MAX($B$6*D19,F19) -> 0.3 | H19: =$B$7 -> ns | I19: =CONCATENATE("set_input_transition -max ",TEXT(G19,"0.000")," [all_inputs]") -> set_input_transition -max 0.300 [all_inputs] | J19: or prefer set_driving_cell; clamp to lib max_tran
A20: Input transition min | B20: all_inputs min slew | C20: % of max transition (not of T) | D20: 0.33 | E20: =D20 -> 0.33 | F20: 0 | G20: =MAX(G19*D20,F20) -> 0.099 | H20: =$B$7 -> ns | I20: =CONCATENATE("set_input_transition -min ",TEXT(G20,"0.000")," [all_inputs]") -> set_input_transition -min 0.099 [all_inputs] | J20: SPECIAL: value = max_tran × this % (see formula)
A21: Clock transition | B21: clock ports | C21: ~50–100 ps class or % T | D21: 0.05 | E21: =D21 -> 0.05 | F21: 0 | G21: =MAX($B$6*D21,F21) -> 0.2 | H21: =$B$7 -> ns | I21: =CONCATENATE("set_clock_transition ",TEXT(G21,"0.000")," [get_clocks ",$B$5,"]") -> set_clock_transition 0.200 [get_clocks CLK] | J21: if not ideal clock
A22: Clock latency (source) | B22: source latency | C22: often absolute, not % T | D22: 0.1 | E22: =D22 -> 0.1 | F22: 0 | G22: =MAX($B$6*D22,F22) -> 0.4 | H22: =$B$7 -> ns | I22: =CONCATENATE("set_clock_latency -source ",TEXT(G22,"0.000")," [get_clocks ",$B$5,"]") -> set_clock_latency -source 0.400 [get_clocks CLK] | J22: board/PLL; early estimate
A23: Clock latency (network) | B23: network pre-CTS | C23: 0 ideal, or small % T | D23: 0 | E23: =D23 -> 0 | F23: 0 | G23: =MAX($B$6*D23,F23) -> 0 | H23: =$B$7 -> ns | I23: =CONCATENATE("set_clock_latency ",TEXT(G23,"0.000")," [get_clocks ",$B$5,"]") -> set_clock_latency 0.000 [get_clocks CLK] | J23: pre-CTS; real after CTS
A24: Output load max | B24: all_outputs | C24: usually absolute (lib cap unit); optional %T only for scale play | D24: 0 | E24: =D24 -> 0 | F24: 0.05 | G24: =IF(D24=0,F24,MAX($B$6*D24,F24)) -> 0.05 | H24: lib cap | I24: =CONCATENATE("set_load -max ",TEXT(G24,"0.000")," [all_outputs]") -> set_load -max 0.050 [all_outputs] | J24: If % = 0 → uses Floor as absolute load. Check liberty cap unit!
A25: Output load min | B25: all_outputs | C25: absolute or %T | D25: 0 | E25: =D25 -> 0 | F25: 0.01 | G25: =IF(D25=0,F25,MAX($B$6*D25,F25)) -> 0.01 | H25: lib cap | I25: =CONCATENATE("set_load -min ",TEXT(G25,"0.000")," [all_outputs]") -> set_load -min 0.010 [all_outputs] | J25: If % = 0 → uses Floor as absolute load
A27: BUDGET SANITY — external delay + uncertainty vs period
A28: Input max + Output max + Setup unc | B28: =G15+G17+G13 -> 2.6 | C28: sum of key setup external budgets | D28: as % of T | E28: =IF($B$6=0,0,B28/$B$6) -> 0.65
A29: Remaining for internal logic (T − sum) | B29: =$B$6-B28 -> 1.4 | C29: rough R2R window after I/O+unc (idealized) | D29: as % of T | E29: =IF($B$6=0,0,B29/$B$6) -> 0.35
A30: Status | B30: =IF(B29<=0,"FAIL — external budgets ≥ T",IF(E28>0.8,"TIGHT — >80% period in I/O+unc",IF(E28>0.6,"OK-ish — watch QoR","COMFORTABLE"))) -> OK-ish — watch QoR
A32: GENERATED SDC STARTER KIT (copy into .sdc — replace [all_inputs] exclusions for clk as needed)
A33: =CONCATENATE("create_clock -name ",$B$5," -period ",TEXT($B$6,"0.000")," [get_ports clk]") -> create_clock -name CLK -period 4.000 [get_ports clk]
A34: =I13 -> set_clock_uncertainty -setup 0.200 [get_clocks CLK]
A35: =I14 -> set_clock_uncertainty -hold 0.080 [get_clocks CLK]
A36: =I15 -> set_input_delay -max 1.200 -clock CLK [all_inputs]
A37: =I16 -> set_input_delay -min 0.400 -clock CLK [all_inputs]
A38: =I17 -> set_output_delay -max 1.200 -clock CLK [all_outputs]
A39: =I18 -> set_output_delay -min 0.400 -clock CLK [all_outputs]
A40: =I19 -> set_input_transition -max 0.300 [all_inputs]
A41: =I20 -> set_input_transition -min 0.099 [all_inputs]
A42: =I24 -> set_load -max 0.050 [all_outputs]
A43: =I25 -> set_load -min 0.010 [all_outputs]
A44: =CONCATENATE("# Period T=",TEXT($B$6,"0.000")," ",$B$7," | f=",TEXT($B$8,"0.00")," MHz | generated by SDC Formulation Calculator") -> # Period T=4.000 ns | f=250.00 MHz | generated by SDC Formulation Calculator
...

Sheet Thumb Rules
A1: SDC thumb-rule reference bands (% of period T)
A3: Parameter | B3: Aggressive | C3: Typical early synth | D3: Conservative | E3: Lab example (T=2ns) | F3: Unit notes
A4: Setup uncertainty | B4: 2–3% | C4: 3–7% (often 5%) | D4: 8–10%+ | E4: 1% (20 ps) mild learning | F4: or floor 50–100 ps
A5: Hold uncertainty | B5: small / 1% | C5: 1–3% or 20–50 ps | D5: larger | E5: 0.5% (10 ps) | F5: floor often 20–50 ps
A6: Input delay max | B6: 10–20% | C6: 20–40% (often 30%) | D6: 40–60% | E6: 10% (0.2 ns) light | F6: external launch
A7: Input delay min | B7: near 0 | C7: 0–10% (~¼–½ of max) | D7: higher min | E7: 0.05 ns | F7: hold on I2R
A8: Output delay max | B8: 10–20% | C8: 20–40% (often 30%) | D8: 40–60% | E8: 10% (0.2 ns) | F8: external capture
A9: Output delay min | B9: near 0 | C9: 0–10% | D9: higher | E9: 0.05 ns | F9: hold on R2O
A10: Input transition max | B10: fast / low % | C10: 5–15% T or 50–150 ps | D10: slow | E10: 0.15 ns | F10: prefer driving_cell
A11: Input transition min | B11: ~20% of max | C11: 30–50% of max | D11: higher | E11: 0.05 ns | F11: % of max tran not T
A12: Output load | B12: under-load | C12: lib pin / board model | D12: over-load | E12: 0.05 (check unit) | F12: NOT usually % of T
A13: Clock latency source | B13: from PLL | C13: 0.1–0.5 ns early | D13: board + package | E13: — | F13: often absolute
A15: Formulas used in Calculator
A16: value = MAX(Period_T × Percentile, Floor)
A17: input_transition_min = MAX(input_transition_max × Percentile, Floor)
A18: load (when % = 0): value = Floor (absolute cap in liberty units)
A19: budget_sum = input_delay_max + output_delay_max + setup_uncertainty
A20: remaining_for_logic ≈ T − budget_sum (idealized; ignores clock network, derates, pads arcs)
A22: Warnings
A23: • These are starting points for synthesis / early STA — not foundry law.
A24: • Do not double-count pad arcs + large I/O delays.
A25: • Do not stack huge uncertainty + huge AOCV derates blindly.
A26: • Always exclude clock port from all_inputs when applying input delay/transition.
A27: • Check capacitance units (fF vs pF) for set_load vs liberty.
A28: • Signoff uncertainty comes from project STA cookbook (jitter, AOCV, CRPR, SI).

Sheet Presets
A1: One-click style presets — copy the % column into Calculator!D13:D23 (and loads separately)
A3: Parameter | B3: Aggressive | C3: Typical (default) | D3: Conservative | E3: Calculator row
A4: Setup uncertainty | B4: 0.03 | C4: 0.05 | D4: 0.1 | E4: 13
A5: Hold uncertainty | B5: 0.01 | C5: 0.02 | D5: 0.03 | E5: 14
A6: Input delay max | B6: 0.15 | C6: 0.3 | D6: 0.45 | E6: 15
A7: Input delay min | B7: 0.02 | C7: 0.1 | D7: 0.15 | E7: 16
A8: Output delay max | B8: 0.15 | C8: 0.3 | D8: 0.45 | E8: 17
A9: Output delay min | B9: 0.02 | C9: 0.1 | D9: 0.15 | E9: 18
A10: Input transition max | B10: 0.05 | C10: 0.075 | D10: 0.12 | E10: 19
A11: Input transition min (of max_tran) | B11: 0.25 | C11: 0.33 | D11: 0.5 | E11: 20
A12: Clock transition | B12: 0.03 | C12: 0.05 | D12: 0.08 | E12: 21
A13: Clock latency source | B13: 0.05 | C13: 0.1 | D13: 0.15 | E13: 22
A14: Clock latency network | B14: 0 | C14: 0 | D14: 0.05 | E14: 23
A16: How to apply a preset
A17: 1. Choose a column (Aggressive / Typical / Conservative).
A18: 2. Copy B4:B14 (or C or D) → paste Special → Values into Calculator D13:D23.
A19: 3. Adjust Floor column and loads on Calculator as needed.
A20: 4. Review Budget Sanity status and generated SDC.
A22: Live comparison at Calculator period T
A23: Parameter | B23: Aggressive value | C23: Typical value | D23: Conservative value
A24: Setup uncertainty | B24: ='SDC Calculator'!$B$6*B4 -> 0.12 | C24: ='SDC Calculator'!$B$6*C4 -> 0.2 | D24: ='SDC Calculator'!$B$6*D4 -> 0.4
A25: Hold uncertainty | B25: ='SDC Calculator'!$B$6*B5 -> 0.04 | C25: ='SDC Calculator'!$B$6*C5 -> 0.08 | D25: ='SDC Calculator'!$B$6*D5 -> 0.12
A26: Input delay max | B26: ='SDC Calculator'!$B$6*B6 -> 0.6 | C26: ='SDC Calculator'!$B$6*C6 -> 1.2 | D26: ='SDC Calculator'!$B$6*D6 -> 1.8
A27: Input delay min | B27: ='SDC Calculator'!$B$6*B7 -> 0.08 | C27: ='SDC Calculator'!$B$6*C7 -> 0.4 | D27: ='SDC Calculator'!$B$6*D7 -> 0.6
A28: Output delay max | B28: ='SDC Calculator'!$B$6*B8 -> 0.6 | C28: ='SDC Calculator'!$B$6*C8 -> 1.2 | D28: ='SDC Calculator'!$B$6*D8 -> 1.8
A29: Output delay min | B29: ='SDC Calculator'!$B$6*B9 -> 0.08 | C29: ='SDC Calculator'!$B$6*C9 -> 0.4 | D29: ='SDC Calculator'!$B$6*D9 -> 0.6
A30: Input transition max | B30: ='SDC Calculator'!$B$6*B10 -> 0.2 | C30: ='SDC Calculator'!$B$6*C10 -> 0.3 | D30: ='SDC Calculator'!$B$6*D10 -> 0.48
A31: Input transition min (of max_tran) | B31: ='SDC Calculator'!$B$6*B11 -> 1 | C31: ='SDC Calculator'!$B$6*C11 -> 1.32 | D31: ='SDC Calculator'!$B$6*D11 -> 2
A32: Clock transition | B32: ='SDC Calculator'!$B$6*B12 -> 0.12 | C32: ='SDC Calculator'!$B$6*C12 -> 0.2 | D32: ='SDC Calculator'!$B$6*D12 -> 0.32
A33: Clock latency source | B33: ='SDC Calculator'!$B$6*B13 -> 0.2 | C33: ='SDC Calculator'!$B$6*C13 -> 0.4 | D33: ='SDC Calculator'!$B$6*D13 -> 0.6
A34: Clock latency network | B34: ='SDC Calculator'!$B$6*B14 -> 0 | C34: ='SDC Calculator'!$B$6*C14 -> 0 | D34: ='SDC Calculator'!$B$6*D14 -> 0.2

Sheet Multi-Clock
A1: Multi-clock batch — enter periods; choose profile %; values auto-fill
A2: Global profile for this sheet (affects default % row): | B2: Typical | C2: ← dropdown
A3: Active % (setup unc / hold / in_max / in_min / out_max / out_min / tran_max)
A4: setup_unc % | B4: =IF($B$2="Aggressive",Presets!B4,IF($B$2="Conservative",Presets!D4,Presets!C4)) -> 0.05 | C4: hold % | D4: =IF($B$2="Aggressive",Presets!B5,IF($B$2="Conservative",Presets!D5,Presets!C5)) -> 0.02 | E4: in_max % | F4: =IF($B$2="Aggressive",Presets!B6,IF($B$2="Conservative",Presets!D6,Presets!C6)) -> 0.3 | G4: in_min % | H4: =IF($B$2="Aggressive",Presets!B7,IF($B$2="Conservative",Presets!D7,Presets!C7)) -> 0.1 | I4: out_max % | J4: =IF($B$2="Aggressive",Presets!B8,IF($B$2="Conservative",Presets!D8,Presets!C8)) -> 0.3 | K4: tran_max % | L4: =IF($B$2="Aggressive",Presets!B10,IF($B$2="Conservative",Presets!D10,Presets!C10)) -> 0.075
A6: Clock | B6: Period T (ns) | C6: Freq (MHz) | D6: Setup unc | E6: Hold unc | F6: Input delay max | G6: Input delay min | H6: Output delay max | I6: Output delay min | J6: Input tran max | K6: Input tran min (33%) | L6: SDC create_clock
A7: CLK | B7: 2 | C7: =IF(OR(B7="",B7=0),"",1000/B7) -> 500 | D7: =IF(B7="","",$B$4*B7) -> 0.1 | E7: =IF(B7="","",$D$4*B7) -> 0.04 | F7: =IF(B7="","",$F$4*B7) -> 0.6 | G7: =IF(B7="","",$H$4*B7) -> 0.2 | H7: =IF(B7="","",$J$4*B7) -> 0.6 | I7: =IF(B7="","",$H$4*B7) -> 0.2 | J7: =IF(B7="","",$L$4*B7) -> 0.15 | K7: =IF(B7="","",J7*0.33) -> 0.0495 | L7: =IF(OR(A7="",B7=""),"",CONCATENATE("create_clock -name ",A7," -period ",TEXT(B7,"0.000")," [get_ports ",LOWER(A7),"]")) -> create_clock -name CLK -period 2.000 [get_ports clk]
A8: CLK_FAST | B8: 1 | C8: =IF(OR(B8="",B8=0),"",1000/B8) -> 1000 | D8: =IF(B8="","",$B$4*B8) -> 0.05 | E8: =IF(B8="","",$D$4*B8) -> 0.02 | F8: =IF(B8="","",$F$4*B8) -> 0.3 | G8: =IF(B8="","",$H$4*B8) -> 0.1 | H8: =IF(B8="","",$J$4*B8) -> 0.3 | I8: =IF(B8="","",$H$4*B8) -> 0.1 | J8: =IF(B8="","",$L$4*B8) -> 0.075 | K8: =IF(B8="","",J8*0.33) -> 0.02475 | L8: =IF(OR(A8="",B8=""),"",CONCATENATE("create_clock -name ",A8," -period ",TEXT(B8,"0.000")," [get_ports ",LOWER(A8),"]")) -> create_clock -name CLK_FAST -period 1.000 [get_ports clk_fast]
A9: CLK_SLOW | B9: 4 | C9: =IF(OR(B9="",B9=0),"",1000/B9) -> 250 | D9: =IF(B9="","",$B$4*B9) -> 0.2 | E9: =IF(B9="","",$D$4*B9) -> 0.08 | F9: =IF(B9="","",$F$4*B9) -> 1.2 | G9: =IF(B9="","",$H$4*B9) -> 0.4 | H9: =IF(B9="","",$J$4*B9) -> 1.2 | I9: =IF(B9="","",$H$4*B9) -> 0.4 | J9: =IF(B9="","",$L$4*B9) -> 0.3 | K9: =IF(B9="","",J9*0.33) -> 0.099 | L9: =IF(OR(A9="",B9=""),"",CONCATENATE("create_clock -name ",A9," -period ",TEXT(B9,"0.000")," [get_ports ",LOWER(A9),"]")) -> create_clock -name CLK_SLOW -period 4.000 [get_ports clk_slow]
C10: =IF(OR(B10="",B10=0),"",1000/B10) | D10: =IF(B10="","",$B$4*B10) | E10: =IF(B10="","",$D$4*B10) | F10: =IF(B10="","",$F$4*B10) | G10: =IF(B10="","",$H$4*B10) | H10: =IF(B10="","",$J$4*B10) | I10: =IF(B10="","",$H$4*B10) | J10: =IF(B10="","",$L$4*B10) | K10: =IF(B10="","",J10*0.33) | L10: =IF(OR(A10="",B10=""),"",CONCATENATE("create_clock -name ",A10," -period ",TEXT(B10,"0.000")," [get_ports ",LOWER(A10),"]"))
C11: =IF(OR(B11="",B11=0),"",1000/B11) | D11: =IF(B11="","",$B$4*B11) | E11: =IF(B11="","",$D$4*B11) | F11: =IF(B11="","",$F$4*B11) | G11: =IF(B11="","",$H$4*B11) | H11: =IF(B11="","",$J$4*B11) | I11: =IF(B11="","",$H$4*B11) | J11: =IF(B11="","",$L$4*B11) | K11: =IF(B11="","",J11*0.33) | L11: =IF(OR(A11="",B11=""),"",CONCATENATE("create_clock -name ",A11," -period ",TEXT(B11,"0.000")," [get_ports ",LOWER(A11),"]"))
A13: Edit yellow Clock / Period cells. Profile dropdown changes all % used in formulas. Add more rows by copying formulas down.

Sheet Lists
A1: Dropdown source lists (for maintenance)
A2: Percentile fractions | B2: Time units | C2: Profiles
A3: 0 | B3: ns | C3: Aggressive
A4: 0.01 | B4: ps | C4: Typical
A5: 0.02 | C5: Conservative
A6: 0.03
A7: 0.05
A8: 0.07
A9: 0.08
A10: 0.1
A11: 0.15
A12: 0.2
A13: 0.25
A14: 0.3
A15: 0.33
A16: 0.35
A17: 0.4
... A19: 0.6
